Workbook

Sheet masterlist
A1: order | B1: count x cond | C1: item | D1: norsk_name | E1: nsl_id_gloss | F1: NSL_sign_start | G1: nsl sign | H1: label check | I1: rsl_id_gloss | J1: rsl_name | K1: RSL_sign_start | L1: rsl sign | M1: NSL motivation | N1: picture_name1 | O1: RSL motivation | P1: motivation match | Q1: control image | R1: picture_name2 | S1: wordclass | T1: boundedness | U1: plurality | V1: homophone | W1: NSL frequency | X1: nsl_log | Y1: Norwegian_Frequency | Z1: norsk_log | AA1: RSL frequency | AB1: rsl_log | AC1: Russian_Frequency | AD1: rusisk_log
A2: 27 | B2: 3 | C2: boy | D2: =CONCATENATE(PROPER(E2),".mp4") -> Gutt.mp4 | E2: gutt | F2: 1700 | G2: https://www.minetegn.no/Tegnordbok-HTML/videos/gutt.mp4 | H2: y | I2: мальчик | J2: =CONCATENATE(A2,".mp4") -> 27.mp4 | K2: 1900 | L2: https://media.spreadthesign.com/video/mp4/12/4095.mp4 | M2: boy with a cap | N2: =CONCATENATE(PROPER(C2)," 1",".jpg") -> Boy 1.jpg | O2: cap | P2: match | Q2: young boy standing without a cap | R2: =CONCATENATE(PROPER(C2)," 2",".jpg") -> Boy 2.jpg | S2: noun | T2: animate | U2: concrete | V2: near | W2: =97+1 -> 98 | X2: =TRUNC(LOG(W2),2) -> 1.99 | Y2: 192.84 | Z2: =TRUNC(LOG(Y2),2) -> 2.28 | AA2: 100 | AB2: =TRUNC(LOG(AA2),2) -> 2 | AC2: 185.04 | AD2: =TRUNC(LOG(AC2),2) -> 2.26
A3: 28 | B3: 4 | C3: children | D3: =CONCATENATE(PROPER(E3),".mp4") -> Barn.mp4 | E3: barn | F3: 1800 | G3: https://www.minetegn.no/Tegnordbok-HTML/videos/barn.mp4 | H3: y | I3: дети | J3: =CONCATENATE(A3,".mp4") -> 28.mp4 | K3: 1900 | L3: https://media.spreadthesign.com/video/mp4/12/16508.mp4 | M3: hands on heads of children at waist level | N3: =CONCATENATE(PROPER(C3)," 1",".jpg") -> Children 1.jpg | O3: short heads | P3: match | Q3: young boys playing with cars | R3: =CONCATENATE(PROPER(C3)," 2",".jpg") -> Children 2.jpg | S3: noun | T3: animate | U3: concrete | V3: exact | W3: =64+7 -> 71 | X3: =TRUNC(LOG(W3),2) -> 1.85 | Y3: 576.79 | Z3: =TRUNC(LOG(Y3),2) -> 2.76 | AA3: 200 | AB3: =TRUNC(LOG(AA3),2) -> 2.3 | AC3: 0.49 | AD3: =TRUNC(LOG(AC3),2) -> -0.3
A4: 31 | B4: 7 | C4: eagle | D4: =CONCATENATE(PROPER(E4),".mp4") -> Ørn.mp4 | E4: ørn | F4: 1400 | G4: https://www.minetegn.no/Tegnordbok-HTML/videos/oern.mp4 | H4: y | I4: орёл | J4: =CONCATENATE(A4,".mp4") -> 31.mp4 | K4: 1700 | L4: https://media.spreadthesign.com/video/mp4/12/13640.mp4 | M4: eagle with focus on beak | N4: =CONCATENATE(PROPER(C4)," 1",".jpg") -> Eagle 1.jpg | O4: eagle with focus on beak | P4: match | Q4: eagle with focus on wings | R4: =CONCATENATE(PROPER(C4)," 2",".jpg") -> Eagle 2.jpg | S4: noun | T4: animate | U4: concrete | V4: near | W4: =1+1 -> 2 | X4: =TRUNC(LOG(W4),2) -> 0.3 | Y4: 1 | Z4: =TRUNC(LOG(Y4),2) -> 0 | AA4: 1 | AB4: =TRUNC(LOG(AA4),2) -> 0 | AC4: 24.97 | AD4: =TRUNC(LOG(AC4),2) -> 1.39
A5: 32 | B5: 8 | C5: family | D5: =CONCATENATE(PROPER(E5),".mp4") -> Familie.mp4 | E5: familie | F5: 1700 | G5: https://www.minetegn.no/Tegnordbok-HTML/videos/familie.mp4 | H5: y | I5: семья | J5: =CONCATENATE(A5,".mp4") -> 32.mp4 | K5: 1600 | L5: https://media.spreadthesign.com/video/mp4/12/43684.mp4 | M5: parents and children holding hands in a ring | N5: =CONCATENATE(PROPER(C5)," 1",".jpg") -> Family 1.jpg | O5: parents and children holding hands in a ring | P5: match | Q5: parents and children holding hands in a line | R5: =CONCATENATE(PROPER(C5)," 2",".jpg") -> Family 2.jpg | S5: noun | T5: animate | U5: concrete | V5: near | W5: 13 | X5: =TRUNC(LOG(W5),2) -> 1.11 | Y5: 1 | Z5: =TRUNC(LOG(Y5),2) -> 0 | AA5: 72 | AB5: =TRUNC(LOG(AA5),2) -> 1.85 | AC5: 234.37 | AD5: =TRUNC(LOG(AC5),2) -> 2.36
A6: 37 | B6: 1 | C6: breathe | D6: =CONCATENATE(PROPER(E6),".mp4") -> Puste.mp4 | E6: puste | F6: 1800 | G6: https://www.minetegn.no/Tegnordbok-HTML/videos/puste.mp4 | H6: y | I6: дышать | J6: =CONCATENATE(A6,".mp4") -> 37.mp4 | K6: 1400 | L6: https://media.spreadthesign.com/video/mp4/12/180136.mp4 | M6: chest movement while breathing | N6: =CONCATENATE(PROPER(C6)," 1",".jpg") -> Breathe 1.jpg | O6: chest movement while breathing | P6: =IF(O6=M6,"match", "nomatch") -> match | Q6: breath coming out of mouth | R6: =CONCATENATE(PROPER(C6)," 2",".jpg") -> Breathe 2.jpg | S6: verb | T6: atelic | U6: intrans | V6: exact | W6: 4 | X6: =TRUNC(LOG(W6),2) -> 0.6 | Y6: 16.08 | Z6: =TRUNC(LOG(Y6),2) -> 1.2 | AA6: 6 | AB6: =TRUNC(LOG(AA6),2) -> 0.77 | AC6: 66.6 | AD6: =TRUNC(LOG(AC6),2) -> 1.82
A7: 38 | B7: 2 | C7: cry | D7: =CONCATENATE(PROPER(E7),".mp4") -> Gråte.mp4 | E7: gråte | F7: 1500 | G7: https://www.minetegn.no/Tegnordbok-HTML/videos/graate-1.mp4 | H7: y | I7: плакать | J7: =CONCATENATE(A7,".mp4") -> 38.mp4 | K7: 1900 | L7: https://media.spreadthesign.com/video/mp4/12/18934.mp4 | M7: tears running down cheek | N7: =CONCATENATE(PROPER(C7)," 1",".jpg") -> Cry 1.jpg | O7: comic book tears and anguished face | P7: match | Q7: hold head in hands crying | R7: =CONCATENATE(PROPER(C7)," 2",".jpg") -> Cry 2.jpg | S7: verb | T7: atelic | U7: intrans | V7: near | W7: 2 | X7: =TRUNC(LOG(W7),2) -> 0.3 | Y7: 19.09 | Z7: =TRUNC(LOG(Y7),2) -> 1.28 | AA7: 15 | AB7: =TRUNC(LOG(AA7),2) -> 1.17 | AC7: 131.77 | AD7: =TRUNC(LOG(AC7),2) -> 2.11
A8: 43 | B8: 7 | C8: run | D8: =CONCATENATE(PROPER(E8),".mp4") -> Løpe.mp4 | E8: løpe | F8: 1600 | G8: https://www.minetegn.no/Tegnordbok-HTML/videos/loepe-2.mp4 | H8: y | I8: бежать | J8: =CONCATENATE(A8,".mp4") -> 43.mp4 | K8: 1600 | L8: https://media.spreadthesign.com/video/mp4/12/15558.mp4 | M8: legs running | N8: =CONCATENATE(PROPER(C8)," 1",".jpg") -> Run 1.jpg | O8: legs | P8: match | Q8: upperbody running | R8: =CONCATENATE(PROPER(C8)," 2",".jpg") -> Run 2.jpg | S8: verb | T8: atelic | U8: intrans | V8: exact | W8: 14 | X8: =TRUNC(LOG(W8),2) -> 1.14 | Y8: 68.88 | Z8: =TRUNC(LOG(Y8),2) -> 1.83 | AA8: 150 | AB8: =TRUNC(LOG(AA8),2) -> 2.17 | AC8: 180.38 | AD8: =TRUNC(LOG(AC8),2) -> 2.25
A9: 44 | B9: 8 | C9: sing | D9: =CONCATENATE(PROPER(E9),".mp4") -> Synge.mp4 | E9: synge | F9: 1400 | G9: https://www.minetegn.no/Tegnordbok-HTML/videos/synge.mp4 | H9: y | I9: петь | J9: =CONCATENATE(A9,".mp4") -> 44.mp4 | K9: 1600 | L9: https://media.spreadthesign.com/video/mp4/12/24057.mp4 | M9: moving hands with tempo | N9: =CONCATENATE(PROPER(C9)," 1",".jpg") -> Sing 1.jpg | O9: moving hands with tempo | P9: =IF(O9=M9,"match", "nomatch") -> match | Q9: singing into microphone | R9: =CONCATENATE(PROPER(C9)," 2",".jpg") -> Sing 2.jpg | S9: verb | T9: atelic | U9: intrans | V9: near | W9: 1 | X9: =TRUNC(LOG(W9),2) -> 0 | Y9: 68.11 | Z9: =TRUNC(LOG(Y9),2) -> 1.83 | AA9: 9 | AB9: =TRUNC(LOG(AA9),2) -> 0.95 | AC9: 148.03 | AD9: =TRUNC(LOG(AC9),2) -> 2.17
A10: 46 | B10: 10 | C10: think | D10: =CONCATENATE(PROPER(E10),".mp4") -> Tror.mp4 | E10: tror | F10: 1300 | G10: https://www.minetegn.no/Tegnordbok-HTML/videos/tror.mp4 | H10: y | I10: думать | J10: =CONCATENATE(A10,".mp4") -> 46.mp4 | K10: 1700 | L10: https://media.spreadthesign.com/video/mp4/12/4904.mp4 | M10: tapping head | N10: =CONCATENATE(PROPER(C10)," 1",".jpg") -> Think 1.jpg | O10: tap head | P10: match | Q10: head tilted to side thinking | R10: =CONCATENATE(PROPER(C10)," 2",".jpg") -> Think 2.jpg | S10: verb | T10: atelic | U10: intrans | V10: exact | W10: =5+108 -> 113 | X10: =TRUNC(LOG(W10),2) -> 2.05 | Y10: 740.5 | Z10: =TRUNC(LOG(Y10),2) -> 2.86 | AA10: 200 | AB10: =TRUNC(LOG(AA10),2) -> 2.3 | AC10: 809.44 | AD10: =TRUNC(LOG(AC10),2) -> 2.9
A11: 42 | B11: 6 | C11: paint | D11: =CONCATENATE(PROPER(E11),".mp4") -> Male.mp4 | E11: male | F11: 1500 | G11: https://www.minetegn.no/Tegnordbok-HTML/videos/male-2.mp4 | H11: y | I11: рисовать | J11: =CONCATENATE(A11,".mp4") -> 42.mp4 | K11: 1800 | L11: https://media.spreadthesign.com/video/mp4/12/16802.mp4 | M11: paint (holding a paintbrush) | N11: =CONCATENATE(PROPER(C11)," 1",".jpg") -> Paint 1.jpg | O11: paint (holding a paintbrush) | P11: =IF(O11=M11,"match", "nomatch") -> match | Q11: paint a wall | R11: =CONCATENATE(PROPER(C11)," 2",".jpg") -> Paint 2.jpg | S11: verb | T11: atelic | U11: trans | V11: near | W11: =1+5 -> 6 | X11: =TRUNC(LOG(W11),2) -> 0.77 | Y11: 740.5 | Z11: =TRUNC(LOG(Y11),2) -> 2.86 | AA11: 33 | AB11: =TRUNC(LOG(AA11),2) -> 1.51 | AC11: 42.66 | AD11: =TRUNC(LOG(AC11),2) -> 1.63
A12: 47 | B12: 11 | C12: watch | D12: Se-på.mp4 | E12: se-på | F12: 1200 | G12: https://www.minetegn.no/Tegnordbok-HTML/videos/se.mp4 | H12: y | I12: смотреть | J12: =CONCATENATE(A12,".mp4") -> 47.mp4 | K12: 1500 | L12: https://media.spreadthesign.com/video/mp4/12/16969.mp4 | M12: eyes looking | N12: =CONCATENATE(PROPER(C12)," 1",".jpg") -> Watch 1.jpg | O12: eyes looking | P12: match | Q12: magnifying glass | R12: =CONCATENATE(PROPER(C12)," 2",".jpg") -> Watch 2.jpg | S12: verb | T12: atelic | U12: trans | V12: near | W12: 59 | X12: =TRUNC(LOG(W12),2) -> 1.77 | Y12: 218.38 | Z12: =TRUNC(LOG(Y12),2) -> 2.33 | AA12: 500 | AB12: =TRUNC(LOG(AA12),2) -> 2.69 | AC12: 634.29 | AD12: =TRUNC(LOG(AC12),2) -> 2.8
A13: 48 | B13: 12 | C13: write | D13: =CONCATENATE(PROPER(E13),".mp4") -> Skrive.mp4 | E13: skrive | F13: 1500 | G13: https://www.minetegn.no/Tegnordbok-HTML/videos/skrive.mp4 | H13: y | I13: писать | J13: =CONCATENATE(A13,".mp4") -> 48.mp4 | K13: 1700 | L13: https://media.spreadthesign.com/video/mp4/12/5223.mp4 | M13: holding a pen and writing | N13: =CONCATENATE(PROPER(C13)," 1",".jpg") -> Write 1.jpg | O13: holding a pen and writing | P13: match | Q13: cursive word in lines from writers perspective | R13: =CONCATENATE(PROPER(C13)," 2",".jpg") -> Write 2.jpg | S13: verb | T13: atelic | U13: trans | V13: near | W13: =2+2 -> 4 | X13: =TRUNC(LOG(W13),2) -> 0.6 | Y13: 926.23 | Z13: =TRUNC(LOG(Y13),2) -> 2.96 | AA13: 66 | AB13: =TRUNC(LOG(AA13),2) -> 1.81 | AC13: 572.69 | AD13: =TRUNC(LOG(AC13),2) -> 2.75
A14: 25 | B14: 1 | C14: beauty | D14: =CONCATENATE(PROPER(E14),".mp4") -> Pen.mp4 | E14: pen | F14: 1800 | G14: https://www.minetegn.no/Tegnordbok-HTML/videos/pen.mp4 | H14: y | I14: красота | J14: =CONCATENATE(A14,".mp4") -> 25.mp4 | K14: 1300 | L14: https://media.spreadthesign.com/video/mp4/12/181826.mp4 | M14: nice face | N14: =CONCATENATE(PROPER(C14)," 1",".jpg") -> Beauty 1.jpg | O14: nice face | P14: match | Q14: flowers | R14: =CONCATENATE(PROPER(C14)," 2",".jpg") -> Beauty 2.jpg | S14: noun | T14: inanimate | U14: abstract | V14: near | W14: 12 | X14: =TRUNC(LOG(W14),2) -> 1.07 | Y14: 67.27 | Z14: =TRUNC(LOG(Y14),2) -> 1.82 | AA14: 42 | AB14: =TRUNC(LOG(AA14),2) -> 1.62 | AC14: 107.92 | AD14: =TRUNC(LOG(AC14),2) -> 2.03
A15: 34 | B15: 10 | C15: change | D15: =CONCATENATE(PROPER(E15),".mp4") -> Endring.mp4 | E15: endring | F15: 1000 | G15: https://www.minetegn.no/Tegnordbok-HTML/videos/endre-ing.mp4 | H15: y | I15: изменение | J15: =CONCATENATE(A15,".mp4") -> 34.mp4 | K15: 1800 | L15: https://media.spreadthesign.com/video/mp4/12/5786.mp4 | M15: rotation of haircuts on a girl | N15: =CONCATENATE(PROPER(C15)," 1",".jpg") -> Change 1.jpg | O15: rotation | P15: match | Q15: butterfly metamorphosis | R15: =CONCATENATE(PROPER(C15)," 2",".jpg") -> Change 2.jpg | S15: noun | T15: inanimate | U15: abstract | V15: near | W15: 1 | X15: =TRUNC(LOG(W15),2) -> 0 | Y15: 169.28 | Z15: =TRUNC(LOG(Y15),2) -> 2.22 | AA15: 12 | AB15: 0 | AC15: 108.63 | AD15: =TRUNC(LOG(AC15),2) -> 2.03
A16: 26 | B16: 2 | C16: book | D16: =CONCATENATE(PROPER(E16),".mp4") -> Bok.mp4 | E16: bok | F16: 1400 | G16: https://www.minetegn.no/Tegnordbok-HTML/videos/bok.mp4 | H16: y | I16: книга | J16: =CONCATENATE(A16,".mp4") -> 26.mp4 | K16: 1700 | L16: https://media.spreadthesign.com/video/mp4/12/18692.mp4 | M16: book that is open | N16: =CONCATENATE(PROPER(C16)," 1",".jpg") -> Book 1.jpg | O16: opening a book | P16: match | Q16: closed book on a table | R16: =CONCATENATE(PROPER(C16)," 2",".jpg") -> Book 2.jpg | S16: noun | T16: inanimate | U16: concrete | V16: exact | W16: 4 | X16: =TRUNC(LOG(W16),2) -> 0.6 | Y16: 361.42 | Z16: =TRUNC(LOG(Y16),2) -> 2.55 | AA16: 12 | AB16: =TRUNC(LOG(AA16),2) -> 1.07 | AC16: 475.75 | AD16: =TRUNC(LOG(AC16),2) -> 2.67
A17: 29 | B17: 5 | C17: coffee | D17: =CONCATENATE(PROPER(E17),".mp4") -> Kaffe.mp4 | E17: kaffe | F17: 1500 | G17: https://www.minetegn.no/Tegnordbok-HTML/videos/kaffe.mp4 | H17: y | I17: кофе | J17: =CONCATENATE(A17,".mp4") -> 29.mp4 | K17: 1900 | L17: https://media.spreadthesign.com/video/mp4/12/8207.mp4 | M17: grinding beans with a hand grinder | N17: =CONCATENATE(PROPER(C17)," 1",".jpg") -> Coffee 1.jpg | O17: grinding beans | P17: match | Q17: steaming cup of coffee | R17: =CONCATENATE(PROPER(C17)," 2",".jpg") -> Coffee 2.jpg | S17: noun | T17: inanimate | U17: concrete | V17: exact | W17: 5 | X17: =TRUNC(LOG(W17),2) -> 0.69 | Y17: 39.72 | Z17: =TRUNC(LOG(Y17),2) -> 1.59 | AA17: 1 | AB17: =TRUNC(LOG(AA17),2) -> 0 | AC17: 49.54 | AD17: =TRUNC(LOG(AC17),2) -> 1.69
A18: 30 | B18: 6 | C18: cigar | D18: =CONCATENATE(PROPER(E18),".mp4") -> Sigar.mp4 | E18: sigar | F18: 1400 | G18: https://www.minetegn.no/Tegnordbok-HTML/videos/sigar.mp4 | H18: y | I18: чашка | J18: =CONCATENATE(A18,".mp4") -> 30.mp4 | K18: 1900 | L18: https://media.spreadthesign.com/video/mp4/12/99766.mp4 | M18: cigar held at mouth | N18: =CONCATENATE(PROPER(C18)," 1",".jpg") -> Cigar 1.jpg | O18: cigar held at mouth | P18: match | Q18: cigar held away from mouth | R18: =CONCATENATE(PROPER(C18)," 2",".jpg") -> Cigar 2.jpg | S18: noun | T18: inanimate | U18: concrete | V18: exact | W18: 2 | X18: =TRUNC(LOG(W18),2) -> 0.3 | Y18: 4.67 | Z18: =TRUNC(LOG(Y18),2) -> 0.66 | AA18: 1 | AB18: =TRUNC(LOG(AA18),2) -> 0 | AC18: 35.12 | AD18: =TRUNC(LOG(AC18),2) -> 1.54
A19: 33 | B19: 9 | C19: flower | D19: =CONCATENATE(PROPER(E19),".mp4") -> Blomst.mp4 | E19: blomst | F19: 1400 | G19: https://www.minetegn.no/Tegnordbok-HTML/videos/blomst-1.mp4 | H19: y | I19: цветок | J19: =CONCATENATE(A19,".mp4") -> 33.mp4 | K19: 2100 | L19: https://media.spreadthesign.com/video/mp4/12/13929.mp4 | M19: scent coming to nose from a flower | N19: =CONCATENATE(PROPER(C19)," 1",".jpg") -> Flower 1.jpg | O19: scent coming to nose from a flower | P19: match | Q19: a single flower in a pot | R19: =CONCATENATE(PROPER(C19)," 2",".jpg") -> Flower 2.jpg | S19: noun | T19: inanimate | U19: concrete | V19: near | W19: 1 | X19: =TRUNC(LOG(W19),2) -> 0 | Y19: 23.2 | Z19: =TRUNC(LOG(Y19),2) -> 1.36 | AA19: 29 | AB19: =TRUNC(LOG(AA19),2) -> 1.46 | AC19: 85.53 | AD19: =TRUNC(LOG(AC19),2) -> 1.93
A20: 35 | B20: 11 | C20: metal | D20: =CONCATENATE(PROPER(E20),".mp4") -> Metall.mp4 | E20: metall | F20: 1800 | G20: https://www.minetegn.no/Tegnordbok-HTML/videos/metall.mp4 | H20: y | I20: металл | J20: =CONCATENATE(A20,".mp4") -> 35.mp4 | K20: 1800 | L20: https://media.spreadthesign.com/video/mp4/12/176203.mp4 | M20: smith hitting metal | N20: =CONCATENATE(PROPER(C20)," 1",".jpg") -> Metal 1.jpg | O20: smith hitting metal | P20: =IF(O20=M20,"match", "nomatch") -> match | Q20: shiny metal surface | R20: =CONCATENATE(PROPER(C20)," 2",".jpg") -> Metal 2.jpg | S20: noun | T20: inanimate | U20: concrete | V20: exact | W20: 4 | X20: =TRUNC(LOG(W20),2) -> 0.6 | Y20: 1 | Z20: =TRUNC(LOG(Y20),2) -> 0 | AA20: 3 | AB20: =TRUNC(LOG(AA20),2) -> 0.47 | AC20: 44.03 | AD20: =TRUNC(LOG(AC20),2) -> 1.64
A21: 36 | B21: 12 | C21: telephone | D21: =CONCATENATE(PROPER(E21),".mp4") -> Telefon.mp4 | E21: telefon | F21: 1700 | G21: https://www.minetegn.no/Tegnordbok-HTML/videos/telefon.mp4 | H21: y | I21: телефон | J21: =CONCATENATE(A21,".mp4") -> 36.mp4 | K21: 1900 | L21: https://media.spreadthesign.com/video/mp4/12/13844.mp4 | M21: shape of the receiver | N21: =CONCATENATE(PROPER(C21)," 1",".jpg") -> Telephone 1.jpg | O21: shape of the receiver | P21: =IF(O21=M21,"match", "nomatch") -> match | Q21: phone in a phonebooth | R21: =CONCATENATE(PROPER(C21)," 2",".jpg") -> Telephone 2.jpg | S21: noun | T21: inanimate | U21: concrete | V21: exact | W21: 9 | X21: =TRUNC(LOG(W21),2) -> 0.95 | Y21: 130.87 | Z21: =TRUNC(LOG(Y21),2) -> 2.11 | AA21: 17 | AB21: =TRUNC(LOG(AA21),2) -> 1.23 | AC21: 120.76 | AD21: =TRUNC(LOG(AC21),2) -> 2.08
A22: 39 | B22: 3 | C22: jump | D22: =CONCATENATE(PROPER(E22),".mp4") -> Hoppe.mp4 | E22: hoppe | F22: 1600 | G22: https://www.minetegn.no/Tegnordbok-HTML/videos/hoppe-opp-og-ned.mp4 | H22: y | I22: прыгать | J22: =CONCATENATE(A22,".mp4") -> 39.mp4 | K22: 1700 | L22: https://media.spreadthesign.com/video/mp4/12/19434.mp4 | M22: legs jumping up | N22: =CONCATENATE(PROPER(C22)," 1",".jpg") -> Jump 1.jpg | O22: legs jumping up | P22: =IF(O22=M22,"match", "nomatch") -> match | Q22: jumping over somthing | R22: =CONCATENATE(PROPER(C22)," 2",".jpg") -> Jump 2.jpg | S22: verb | T22: telic | U22: intrans | V22: exact | W22: 2 | X22: =TRUNC(LOG(W22),2) -> 0.3 | Y22: 45.4 | Z22: =TRUNC(LOG(Y22),2) -> 1.65 | AA22: 8 | AB22: =TRUNC(LOG(AA22),2) -> 0.9 | AC22: 33.8 | AD22: =TRUNC(LOG(AC22),2) -> 1.52
A23: 40 | B23: 4 | C23: leave | D23: Stikke-av.mp4 | E23: stikke-av | F23: 2100 | G23: https://www.minetegn.no/Tegnordbok-HTML/videos/dra.mp4 | H23: y | I23: уйти | J23: =CONCATENATE(A23,".mp4") -> 40.mp4 | K23: 1600 | L23: https://media.spreadthesign.com/video/mp4/12/4996.mp4 | M23: figure moving away and getting smaller | N23: =CONCATENATE(PROPER(C23)," 1",".jpg") -> Leave 1.jpg | O23: figure moving away and getting smaller | P23: =IF(O23=M23,"match", "nomatch") -> match | Q23: going out a door | R23: =CONCATENATE(PROPER(C23)," 2",".jpg") -> Leave 2.jpg | S23: verb | T23: telic | U23: trans | V23: exact | W23: =2+1 -> 3 | X23: =TRUNC(LOG(W23),2) -> 0.47 | Y23: 212.49 | Z23: =TRUNC(LOG(Y23),2) -> 2.32 | AA23: 150 | AB23: =TRUNC(LOG(AA23),2) -> 2.17 | AC23: 318.89 | AD23: =TRUNC(LOG(AC23),2) -> 2.5
A24: 41 | B24: 5 | C24: lose | D24: =CONCATENATE(PROPER(E24),".mp4") -> Miste.mp4 | E24: miste | F24: 900 | G24: https://www.minetegn.no/Tegnordbok-HTML/videos/miste.mp4 | H24: y | I24: терять | J24: =CONCATENATE(A24,".mp4") -> 41.mp4 | K24: 1500 | L24: https://youtu.be/OWNW0gJdFf8 | M24: dropping plates | N24: =CONCATENATE(PROPER(C24)," 1",".jpg") -> Lose 1.jpg | O24: dropping | P24: match | Q24: searching for something | R24: =CONCATENATE(PROPER(C24)," 2",".jpg") -> Lose 2.jpg | S24: verb | T24: telic | U24: trans | V24: near | W24: 5 | X24: =TRUNC(LOG(W24),2) -> 0.69 | Y24: 125.04 | Z24: =TRUNC(LOG(Y24),2) -> 2.09 | AA24: 3 | AB24: =TRUNC(LOG(AA24),2) -> 0.47 | AC24: 70.97 | AD24: =TRUNC(LOG(AC24),2) -> 1.85
A25: 45 | B25: 9 | C25: take | D25: =CONCATENATE(PROPER(E25),".mp4") -> Ta.mp4 | E25: ta | F25: 1400 | G25: https://www.minetegn.no/Tegnordbok-HTML/videos/ta.mp4 | H25: y | I25: взять | J25: =CONCATENATE(A25,".mp4") -> 45.mp4 | K25: 1700 | L25: https://media.spreadthesign.com/video/mp4/12/5685.mp4 | M25: taking hand (grasp) | N25: =CONCATENATE(PROPER(C25)," 1",".jpg") -> Take 1.jpg | O25: taking hand (grasp) | P25: match | Q25: pinch by taking up an object | R25: =CONCATENATE(PROPER(C25)," 2",".jpg") -> Take 2.jpg | S25: verb | T25: telic | U25: trans | V25: near | W25: =50+4 -> 54 | X25: =TRUNC(LOG(W25),2) -> 1.73 | Y25: 2028.09 | Z25: =TRUNC(LOG(Y25),2) -> 3.3 | AA25: 150 | AB25: =TRUNC(LOG(AA25),2) -> 2.17 | AC25: 605.11 | AD25: =TRUNC(LOG(AC25),2) -> 2.78
A26: 6 | B26: 6 | C26: frog | D26: =CONCATENATE(PROPER(E26),".mp4") -> Frosk.mp4 | E26: frosk | F26: 1400 | G26: https://www.minetegn.no/Tegnordbok-HTML/videos/frosk.mp4 | H26: y | I26: лягушка | J26: =CONCATENATE(A26,".mp4") -> 6.mp4 | K26: 1700 | L26: https://media.spreadthesign.com/video/mp4/12/13598.mp4 | M26: vocal sack | N26: =CONCATENATE(PROPER(C26)," 1",".jpg") -> Frog 1.jpg | O26: spadefoots (maybe show full frog) | P26: nomatch | Q26: na | R26: =CONCATENATE(PROPER(C26)," 2",".jpg") -> Frog 2.jpg | S26: noun | T26: animate | U26: concrete | V26: different | W26: 18 | X26: =TRUNC(LOG(W26),2) -> 1.25 | Y26: 3.94 | Z26: =TRUNC(LOG(Y26),2) -> 0.59 | AA26: 1 | AB26: =TRUNC(LOG(AA26),2) -> 0 | AC26: 13.15 | AD26: =TRUNC(LOG(AC26),2) -> 1.11
A27: 7 | B27: 7 | C27: gorilla | D27: =CONCATENATE(PROPER(E27),".mp4") -> Gorilla.mp4 | E27: gorilla | F27: 1300 | G27: https://www.minetegn.no/Tegnordbok-HTML/videos/gorilla.mp4 | H27: y | I27: горилла | J27: =CONCATENATE(A27,".mp4") -> 7.mp4 | K27: 2700 | L27: https://media.spreadthesign.com/video/mp4/12/295313.mp4 | M27: gorilla beating chest | N27: =CONCATENATE(PROPER(C27)," 1",".jpg") -> Gorilla 1.jpg | O27: gorilla doing a flex | P27: =IF(O27=M27,"match", "nomatch") -> nomatch | Q27: na | R27: =CONCATENATE(PROPER(C27)," 2",".jpg") -> Gorilla 2.jpg | S27: noun | T27: animate | U27: concrete | V27: different | W27: 1 | X27: =TRUNC(LOG(W27),2) -> 0 | Y27: 2.19 | Z27: =TRUNC(LOG(Y27),2) -> 0.34 | AA27: 1 | AB27: =TRUNC(LOG(AA27),2) -> 0 | AC27: 1.86 | AD27: =TRUNC(LOG(AC27),2) -> 0.26
A28: 14 | B28: 2 | C28: come | D28: =CONCATENATE(PROPER(E28),".mp4") -> Komme.mp4 | E28: komme | F28: 1600 | G28: https://www.minetegn.no/Tegnbanken-2016/data/hendene/komme-a.jpg | H28: y | I28: прийти | J28: =CONCATENATE(A28,".mp4") -> 14.mp4 | K28: 1900 | L28: https://media.spreadthesign.com/video/mp4/12/5177.mp4 | M28: hand gesture | N28: =CONCATENATE(PROPER(C28)," 1",".jpg") -> Come 1.jpg | O28: legs + orientation change | P28: =IF(O29=M29,"match", "nomatch") -> nomatch | Q28: na | R28: =CONCATENATE(PROPER(C28)," 2",".jpg") -> Come 2.jpg | S28: verb | T28: atelic | U28: intrans | V28: different | W28: =28+11 -> 39 | X28: =TRUNC(LOG(W28),2) -> 1.59 | Y28: 1903.14 | Z28: =TRUNC(LOG(Y28),2) -> 3.27 | AA28: 150 | AB28: =TRUNC(LOG(AA28),2) -> 2.17 | AC28: 588.15 | AD28: =TRUNC(LOG(AC28),2) -> 2.76
A29: 18 | B29: 6 | C29: sail | D29: Seil-båt.mp4 | E29: seil-båt | F29: 1400 | G29: https://www.minetegn.no/Tegnordbok-HTML/videos/seil.mp4 | H29: y | I29: плыть лодка | J29: =CONCATENATE(A29,".mp4") -> 18.mp4 | K29: 1700 | L29: https://media.spreadthesign.com/video/mp4/12/319932.mp4 | M29: a sail moving forward | N29: =CONCATENATE(PROPER(C29)," 1",".jpg") -> Sail 1.jpg | O29: a hull moving forward | P29: nomatch | Q29: na | R29: =CONCATENATE(PROPER(C29)," 2",".jpg") -> Sail 2.jpg | S29: verb | T29: atelic | U29: intrans | V29: different | W29: 1 | X29: =TRUNC(LOG(W29),2) -> 0 | Y29: 16.93 | Z29: =TRUNC(LOG(Y29),2) -> 1.22 | AA29: 1 | AB29: =TRUNC(LOG(AA29),2) -> 0 | AC29: 44.26 | AD29: =TRUNC(LOG(AC29),2) -> 1.64
A30: 21 | B30: 9 | C30: travel | D30: =CONCATENATE(PROPER(E30),".mp4") -> Reise.mp4 | E30: reise | F30: 1400 | G30: https://www.minetegn.no/Tegnordbok-HTML/videos/reise-2.mp4 | H30: y | I30: путешествовать | J30: =CONCATENATE(A30,".mp4") -> 21.mp4 | K30: 2000 | L30: https://media.spreadthesign.com/video/mp4/12/17689.mp4 | M30: sitting while traveling | N30: =CONCATENATE(PROPER(C30)," 1",".jpg") -> Travel 1.jpg | O30: moving from one city to another | P30: =IF(O30=M30,"match", "nomatch") -> nomatch | Q30: na | R30: =CONCATENATE(PROPER(C30)," 2",".jpg") -> Travel 2.jpg | S30: verb | T30: atelic | U30: intrans | V30: different | W30: 24 | X30: =TRUNC(LOG(W30),2) -> 1.38 | Y30: 1 | Z30: =TRUNC(LOG(Y30),2) -> 0 | AA30: 7 | AB30: =TRUNC(LOG(AA30),2) -> 0.84 | AC30: 15 | AD30: =TRUNC(LOG(AC30),2) -> 1.17
A31: 15 | B31: 3 | C31: doubt | D31: =CONCATENATE(PROPER(E31),".mp4") -> Skeptisk.mp4 | E31: skeptisk | F31: 1400 | G31: https://www.minetegn.no/Tegnordbok-HTML/videos/skeptisk.mp4 | H31: y | I31: сомневаться | J31: =CONCATENATE(A31,".mp4") -> 15.mp4 | K31: 2100 | L31: https://media.spreadthesign.com/video/mp4/12/15759.mp4 | M31: rubbing chin | N31: =CONCATENATE(PROPER(C31)," 1",".jpg") -> Doubt 1.jpg | O31: think + scales | P31: =IF(O31=M31,"match", "nomatch") -> nomatch | Q31: na | R31: =CONCATENATE(PROPER(C31)," 2",".jpg") -> Doubt 2.jpg | S31: verb | T31: atelic | U31: trans | V31: different | W31: 1 | X31: =TRUNC(LOG(W31),2) -> 0 | Y31: 26.78 | Z31: =TRUNC(LOG(Y31),2) -> 1.42 | AA31: 2 | AB31: =TRUNC(LOG(AA31),2) -> 0.3 | AC31: 52.54 | AD31: =TRUNC(LOG(AC31),2) -> 1.72
A32: 16 | B32: 4 | C32: play | D32: =CONCATENATE(PROPER(E32),".mp4") -> Spille.mp4 | E32: spille | F32: 1500 | G32: https://www.minetegn.no/Tegnordbok-HTML/videos/spille-brettspill-2.mp4 | H32: y | I32: играть | J32: =CONCATENATE(A32,".mp4") -> 16.mp4 | K32: 1900 | L32: https://media.spreadthesign.com/video/mp4/12/4676.mp4 | M32: chess/checkers | N32: =CONCATENATE(PROPER(C32)," 1",".jpg") -> Play 1.jpg | O32: playing with dolls | P32: =IF(O32=M32,"match", "nomatch") -> nomatch | Q32: na | R32: =CONCATENATE(PROPER(C32)," 2",".jpg") -> Play 2.jpg | S32: verb | T32: atelic | U32: trans | V32: different | W32: =2+1+12 -> 15 | X32: =TRUNC(LOG(W32),2) -> 1.17 | Y32: 438.43 | Z32: =TRUNC(LOG(Y32),2) -> 2.64 | AA32: 72 | AB32: =TRUNC(LOG(AA32),2) -> 1.85 | AC32: 293.17 | AD32: =TRUNC(LOG(AC32),2) -> 2.46
A33: 2 | B33: 2 | C33: engagement | D33: =CONCATENATE(PROPER(E33),".mp4") -> Forlovet.mp4 | E33: forlovet | F33: 1600 | G33: https://www.minetegn.no/Tegnordbok-HTML/videos/forlovet.mp4 | H33: y | I33: помолвка | J33: =CONCATENATE(A33,".mp4") -> 2.mp4 | K33: 2600 | L33: https://media.spreadthesign.com/video/mp4/12/319872.mp4 | M33: two people in wedding attire kissing | N33: =CONCATENATE(PROPER(C33)," 1",".jpg") -> Engagement 1.jpg | O33: placing an engagement ring | P33: nomatch | Q33: na | R33: =CONCATENATE(PROPER(C33)," 2",".jpg") -> Engagement 2.jpg | S33: noun | T33: inanimate | U33: abstract | V33: different | W33: 1 | X33: =TRUNC(LOG(W33),2) -> 0 | Y33: 1 | Z33: =TRUNC(LOG(Y33),2) -> 0 | AA33: 1 | AB33: =TRUNC(LOG(AA33),2) -> 0 | AC33: 1.83 | AD33: =TRUNC(LOG(AC33),2) -> 0.26
A34: 3 | B34: 3 | C34: color | D34: =CONCATENATE(PROPER(E34),".mp4") -> Farge.mp4 | E34: farge | F34: 1400 | G34: https://www.minetegn.no/Tegnordbok-HTML/videos/farge-1.mp4 | H34: y | I34: цвет | J34: =CONCATENATE(A34,".mp4") -> 3.mp4 | K34: 1800 | L34: https://media.spreadthesign.com/video/mp4/12/351382.mp4 | M34: dyed fabric | N34: =CONCATENATE(PROPER(C34)," 1",".jpg") -> Color 1.jpg | O34: applying rouge | P34: =IF(O34=M34,"match", "nomatch") -> nomatch | Q34: na | R34: =CONCATENATE(PROPER(C34)," 2",".jpg") -> Color 2.jpg | S34: noun | T34: inanimate | U34: abstract | V34: different | W34: 7 | X34: =TRUNC(LOG(W34),2) -> 0.84 | Y34: 92.5 | Z34: =TRUNC(LOG(Y34),2) -> 1.96 | AA34: 3 | AB34: =TRUNC(LOG(AA34),2) -> 0.47 | AC34: 134.74 | AD34: =TRUNC(LOG(AC34),2) -> 2.12
A35: 5 | B35: 5 | C35: east | D35: =CONCATENATE(PROPER(E35),".mp4") -> Øst.mp4 | E35: øst | F35: 1500 | G35: https://www.minetegn.no/Tegnordbok-HTML/videos/oest-retning-2.mp4 | H35: y | I35: восток | J35: =CONCATENATE(A35,".mp4") -> 5.mp4 | K35: 1900 | L35: https://media.spreadthesign.com/video/mp4/12/17900.mp4 | M35: movement right | N35: =CONCATENATE(PROPER(C35)," 1",".jpg") -> East 1.jpg | O35: sun rising | P35: nomatch | Q35: na | R35: =CONCATENATE(PROPER(C35)," 2",".jpg") -> East 2.jpg | S35: noun | T35: inanimate | U35: abstract | V35: different | W35: 13 | X35: =TRUNC(LOG(W35),2) -> 1.11 | Y35: 1 | Z35: =TRUNC(LOG(Y35),2) -> 0 | AA35: 1 | AB35: =TRUNC(LOG(AA35),2) -> 0 | AC35: 90.27 | AD35: =TRUNC(LOG(AC35),2) -> 1.95
A36: 11 | B36: 11 | C36: school | D36: =CONCATENATE(PROPER(E36),".mp4") -> Skole.mp4 | E36: skole | F36: 1800 | G36: https://www.minetegn.no/Tegnordbok-HTML/videos/skole.mp4 | H36: y | I36: школа | J36: =CONCATENATE(A36,".mp4") -> 11.mp4 | K36: 1600 | L36: https://media.spreadthesign.com/video/mp4/12/12914.mp4 | M36: reading a book in front of your face | N36: =CONCATENATE(PROPER(C36)," 1",".jpg") -> School 1.jpg | O36: large institute/rectangular shape | P36: =IF(O36=M36,"match", "nomatch") -> nomatch | Q36: na | R36: =CONCATENATE(PROPER(C36)," 2",".jpg") -> School 2.jpg | S36: noun | T36: inanimate | U36: abstract | V36: different | W36: 84 | X36: =TRUNC(LOG(W36),2) -> 1.92 | Y36: 228.71 | Z36: =TRUNC(LOG(Y36),2) -> 2.35 | AA36: 105 | AB36: =TRUNC(LOG(AA36),2) -> 2.02 | AC36: 280.12 | AD36: =TRUNC(LOG(AC36),2) -> 2.44
A37: 12 | B37: 12 | C37: pain | D37: =CONCATENATE(PROPER(E37),".mp4") -> Vondt.mp4 | E37: vondt | F37: 1400 | G37: https://www.minetegn.no/Tegnordbok-HTML/videos/vondt-2.mp4 | H37: y | I37: боль | J37: =CONCATENATE(A37,".mp4") -> 12.mp4 | K37: 1900 | L37: https://media.spreadthesign.com/video/mp4/12/4439.mp4 | M37: pained face from chest pain | N37: =CONCATENATE(PROPER(C37)," 1",".jpg") -> Pain 1.jpg | O37: pained face from nail sticking hand | P37: nomatch | Q37: na | R37: =CONCATENATE(PROPER(C37)," 2",".jpg") -> Pain 2.jpg | S37: noun | T37: inanimate | U37: abstract | V37: different | W37: 2 | X37: =TRUNC(LOG(W37),2) -> 0.3 | Y37: 184.89 | Z37: =TRUNC(LOG(Y37),2) -> 2.26 | AA37: 15 | AB37: =TRUNC(LOG(AA37),2) -> 1.17 | AC37: 99.06 | AD37: =TRUNC(LOG(AC37),2) -> 1.99
A38: 1 | B38: 1 | C38: cabbage | D38: =CONCATENATE(PROPER(E38),".mp4") -> Kåle.mp4 | E38: kåle | F38: 1500 | G38: https://www.minetegn.no/Tegnordbok-HTML/videos/kael.mp4 | H38: y | I38: капуста | J38: =CONCATENATE(A38,".mp4") -> 1.mp4 | K38: 1200 | L38: https://media.spreadthesign.com/video/mp4/12/7724.mp4 | M38: shape of cabbage | N38: =CONCATENATE(PROPER(C38)," 1",".jpg") -> Cabbage 1.jpg | O38: cutting cabbage | P38: =IF(O38=M38,"match", "nomatch") -> nomatch | Q38: na | R38: =CONCATENATE(PROPER(C38)," 2",".jpg") -> Cabbage 2.jpg | S38: noun | T38: inanimate | U38: concrete | V38: different | W38: 1 | X38: =TRUNC(LOG(W38),2) -> 0 | Y38: 2.07 | Z38: =TRUNC(LOG(Y38),2) -> 0.31 | AA38: 4 | AB38: =TRUNC(LOG(AA38),2) -> 0.6 | AC38: 20.24 | AD38: =TRUNC(LOG(AC38),2) -> 1.3
A39: 4 | B39: 4 | C39: doll | D39: =CONCATENATE(PROPER(E39),".mp4") -> Dukke.mp4 | E39: dukke | F39: 1400 | G39: https://www.minetegn.no/Tegnordbok-HTML/videos/dukke-2.mp4 | H39: y | I39: кукла | J39: =CONCATENATE(A39,".mp4") -> 4.mp4 | K39: 2600 | L39: https://media.spreadthesign.com/video/mp4/12/19015.mp4 | M39: holding doll | N39: =CONCATENATE(PROPER(C39)," 1",".jpg") -> Doll 1.jpg | O39: head of the doll | P39: =IF(O39=M39,"match", "nomatch") -> nomatch | Q39: na | R39: =CONCATENATE(PROPER(C39)," 2",".jpg") -> Doll 2.jpg | S39: noun | T39: inanimate | U39: concrete | V39: different | W39: 1 | X39: =TRUNC(LOG(W39),2) -> 0 | Y39: 9.32 | Z39: =TRUNC(LOG(Y39),2) -> 0.96 | AA39: 5 | AB39: =TRUNC(LOG(AA39),2) -> 0.69 | AC39: 21.7 | AD39: =TRUNC(LOG(AC39),2) -> 1.33
A40: 8 | B40: 8 | C40: magazine | D40: =CONCATENATE(PROPER(E40),".mp4") -> Dagbladet.mp4 | E40: dagbladet | F40: 1600 | G40: https://www.minetegn.no/Tegnordbok-HTML/videos/dagbladet.mp4 | H40: y | I40: журнал | J40: =CONCATENATE(A40,".mp4") -> 8.mp4 | K40: 2000 | L40: https://media.spreadthesign.com/video/mp4/12/13863.mp4 | M40: an open magazine | N40: =CONCATENATE(PROPER(C40)," 1",".jpg") -> Magazine 1.jpg | O40: many pages in a magazine | P40: =IF(O40=M40,"match", "nomatch") -> nomatch | Q40: na | R40: =CONCATENATE(PROPER(C40)," 2",".jpg") -> Magazine 2.jpg | S40: noun | T40: inanimate | U40: concrete | V40: different | W40: 1 | X40: =TRUNC(LOG(W40),2) -> 0 | Y40: 108.85 | Z40: =TRUNC(LOG(Y40),2) -> 2.03 | AA40: 11 | AB40: =TRUNC(LOG(AA40),2) -> 1.04 | AC40: 156.79 | AD40: =TRUNC(LOG(AC40),2) -> 2.19
...

Sheet nsl survey
A1: display | B1: item | C1: nsl_id_gloss | D1: norsk_video | E1: picture_name
A2: Instructions
A3: trial | B3: cabbage | C3: =masterlist!E2 -> gutt | D3: =CONCATENATE(PROPER(C3),".mp4") -> Gutt.mp4 | E3: =CONCATENATE(PROPER(B3)," 1",".jpg") -> Cabbage 1.jpg
A4: trial | B4: engagement | C4: =masterlist!E3 -> barn | D4: =CONCATENATE(PROPER(C4),".mp4") -> Barn.mp4 | E4: =CONCATENATE(PROPER(B4)," 1",".jpg") -> Engagement 1.jpg
A5: trial | B5: color | C5: =masterlist!E4 -> ørn | D5: =CONCATENATE(PROPER(C5),".mp4") -> Ørn.mp4 | E5: =CONCATENATE(PROPER(B5)," 1",".jpg") -> Color 1.jpg
A6: trial | B6: doll | C6: =masterlist!E5 -> familie | D6: =CONCATENATE(PROPER(C6),".mp4") -> Familie.mp4 | E6: =CONCATENATE(PROPER(B6)," 1",".jpg") -> Doll 1.jpg
A7: trial | B7: east | C7: =masterlist!E6 -> puste | D7: =CONCATENATE(PROPER(C7),".mp4") -> Puste.mp4 | E7: =CONCATENATE(PROPER(B7)," 1",".jpg") -> East 1.jpg
A8: trial | B8: frog | C8: =masterlist!E7 -> gråte | D8: =CONCATENATE(PROPER(C8),".mp4") -> Gråte.mp4 | E8: =CONCATENATE(PROPER(B8)," 1",".jpg") -> Frog 1.jpg
A9: trial | B9: gorilla | C9: =masterlist!E8 -> løpe | D9: =CONCATENATE(PROPER(C9),".mp4") -> Løpe.mp4 | E9: =CONCATENATE(PROPER(B9)," 1",".jpg") -> Gorilla 1.jpg
A10: trial | B10: magazine | C10: =masterlist!E9 -> synge | D10: =CONCATENATE(PROPER(C10),".mp4") -> Synge.mp4 | E10: =CONCATENATE(PROPER(B10)," 1",".jpg") -> Magazine 1.jpg
A11: trial | B11: ring | C11: =masterlist!E10 -> tror | D11: =CONCATENATE(PROPER(C11),".mp4") -> Tror.mp4 | E11: =CONCATENATE(PROPER(B11)," 1",".jpg") -> Ring 1.jpg
A12: trial | B12: salt | C12: =masterlist!E11 -> male | D12: =CONCATENATE(PROPER(C12),".mp4") -> Male.mp4 | E12: =CONCATENATE(PROPER(B12)," 1",".jpg") -> Salt 1.jpg
A13: trial | B13: school | C13: =masterlist!E12 -> se-på | D13: =CONCATENATE(PROPER(C13),".mp4") -> Se-På.mp4 | E13: =CONCATENATE(PROPER(B13)," 1",".jpg") -> School 1.jpg
A14: trial | B14: pain | C14: =masterlist!E13 -> skrive | D14: =CONCATENATE(PROPER(C14),".mp4") -> Skrive.mp4 | E14: =CONCATENATE(PROPER(B14)," 1",".jpg") -> Pain 1.jpg
... A32: trial | B32: cigar | C32: =masterlist!E31 -> skeptisk | D32: =CONCATENATE(PROPER(C32),".mp4") -> Skeptisk.mp4 | E32: =CONCATENATE(PROPER(B32)," 1",".jpg") -> Cigar 1.jpg
A33: trial | B33: eagle | C33: =masterlist!E32 -> spille | D33: Se-på.mp4 | E33: =CONCATENATE(PROPER(B33)," 1",".jpg") -> Eagle 1.jpg
A34: trial | B34: family | C34: =masterlist!E33 -> forlovet | D34: Seil-båt.mp4 | E34: =CONCATENATE(PROPER(B34)," 1",".jpg") -> Family 1.jpg
A35: trial | B35: flower | C35: =masterlist!E34 -> farge | D35: =CONCATENATE(PROPER(C35),".mp4") -> Farge.mp4 | E35: =CONCATENATE(PROPER(B35)," 1",".jpg") -> Flower 1.jpg
A36: trial | B36: change | C36: =masterlist!E35 -> øst | D36: =CONCATENATE(PROPER(C36),".mp4") -> Øst.mp4 | E36: =CONCATENATE(PROPER(B36)," 1",".jpg") -> Change 1.jpg
A37: trial | B37: metal | C37: =masterlist!E36 -> skole | D37: =CONCATENATE(PROPER(C37),".mp4") -> Skole.mp4 | E37: =CONCATENATE(PROPER(B37)," 1",".jpg") -> Metal 1.jpg
A38: trial | B38: telephone | C38: =masterlist!E37 -> vondt | D38: =CONCATENATE(PROPER(C38),".mp4") -> Vondt.mp4 | E38: =CONCATENATE(PROPER(B38)," 1",".jpg") -> Telephone 1.jpg
A39: trial | B39: breathe | C39: =masterlist!E38 -> kåle | D39: =CONCATENATE(PROPER(C39),".mp4") -> Kåle.mp4 | E39: =CONCATENATE(PROPER(B39)," 1",".jpg") -> Breathe 1.jpg
A40: trial | B40: cry | C40: =masterlist!E39 -> dukke | D40: =CONCATENATE(PROPER(C40),".mp4") -> Dukke.mp4 | E40: =CONCATENATE(PROPER(B40)," 1",".jpg") -> Cry 1.jpg
A41: trial | B41: jump | C41: =masterlist!E40 -> dagbladet | D41: Stikke-av.mp4 | E41: =CONCATENATE(PROPER(B41)," 1",".jpg") -> Jump 1.jpg
A42: trial | B42: leave | C42: =masterlist!E41 -> sirkel | D42: =CONCATENATE(PROPER(C42),".mp4") -> Sirkel.mp4 | E42: =CONCATENATE(PROPER(B42)," 1",".jpg") -> Leave 1.jpg
A43: trial | B43: lose | C43: =masterlist!E42 -> salt | D43: =CONCATENATE(PROPER(C43),".mp4") -> Salt.mp4 | E43: =CONCATENATE(PROPER(B43)," 1",".jpg") -> Lose 1.jpg
A44: trial | B44: paint | C44: =masterlist!E43 -> nyse | D44: =CONCATENATE(PROPER(C44),".mp4") -> Nyse.mp4 | E44: =CONCATENATE(PROPER(B44)," 1",".jpg") -> Paint 1.jpg
A45: trial | B45: run | C45: =masterlist!E44 -> prøve | D45: =CONCATENATE(PROPER(C45),".mp4") -> Prøve.mp4 | E45: =CONCATENATE(PROPER(B45)," 1",".jpg") -> Run 1.jpg
A46: trial | B46: sing | C46: =masterlist!E45 -> vente | D46: =CONCATENATE(PROPER(C46),".mp4") -> Vente.mp4 | E46: =CONCATENATE(PROPER(B46)," 1",".jpg") -> Sing 1.jpg
A47: trial | B47: take | C47: =masterlist!E46 -> rope | D47: =CONCATENATE(PROPER(C47),".mp4") -> Rope.mp4 | E47: =CONCATENATE(PROPER(B47)," 1",".jpg") -> Take 1.jpg
A48: trial | B48: think | C48: =masterlist!E47 -> velge | D48: =CONCATENATE(PROPER(C48),".mp4") -> Velge.mp4 | E48: =CONCATENATE(PROPER(B48)," 1",".jpg") -> Think 1.jpg
A49: trial | B49: watch | C49: =masterlist!E48 -> vise | D49: =CONCATENATE(PROPER(C49),".mp4") -> Vise.mp4 | E49: =CONCATENATE(PROPER(B49)," 1",".jpg") -> Watch 1.jpg
A50: trial | B50: write | C50: =masterlist!E49 -> vinne | D50: =CONCATENATE(PROPER(C50),".mp4") -> Vinne.mp4 | E50: =CONCATENATE(PROPER(B50)," 1",".jpg") -> Write 1.jpg
A51: End

Sheet rsl survey
A1: display | B1: item | C1: rsl_id_gloss | D1: video_name | E1: picture_name
A2: Instructions
A3: trial | B3: =masterlist!C2 -> boy | C3: =masterlist!I2 -> мальчик | D3: =masterlist!J2 -> 27.mp4 | E3: =CONCATENATE(PROPER(B3)," 2",".jpg") -> Boy 2.jpg
A4: trial | B4: =masterlist!C3 -> children | C4: =masterlist!I3 -> дети | D4: =masterlist!J3 -> 28.mp4 | E4: =CONCATENATE(PROPER(B4)," 2",".jpg") -> Children 2.jpg
A5: trial | B5: =masterlist!C4 -> eagle | C5: =masterlist!I4 -> орёл | D5: =masterlist!J4 -> 31.mp4 | E5: =CONCATENATE(PROPER(B5)," 2",".jpg") -> Eagle 2.jpg
A6: trial | B6: =masterlist!C5 -> family | C6: =masterlist!I5 -> семья | D6: =masterlist!J5 -> 32.mp4 | E6: =CONCATENATE(PROPER(B6)," 2",".jpg") -> Family 2.jpg
A7: trial | B7: =masterlist!C6 -> breathe | C7: =masterlist!I6 -> дышать | D7: =masterlist!J6 -> 37.mp4 | E7: =CONCATENATE(PROPER(B7)," 2",".jpg") -> Breathe 2.jpg
A8: trial | B8: =masterlist!C7 -> cry | C8: =masterlist!I7 -> плакать | D8: =masterlist!J7 -> 38.mp4 | E8: =CONCATENATE(PROPER(B8)," 2",".jpg") -> Cry 2.jpg
A9: trial | B9: =masterlist!C8 -> run | C9: =masterlist!I8 -> бежать | D9: =masterlist!J8 -> 43.mp4 | E9: =CONCATENATE(PROPER(B9)," 2",".jpg") -> Run 2.jpg
A10: trial | B10: =masterlist!C9 -> sing | C10: =masterlist!I9 -> петь | D10: =masterlist!J9 -> 44.mp4 | E10: =CONCATENATE(PROPER(B10)," 2",".jpg") -> Sing 2.jpg
A11: trial | B11: =masterlist!C10 -> think | C11: =masterlist!I10 -> думать | D11: =masterlist!J10 -> 46.mp4 | E11: =CONCATENATE(PROPER(B11)," 2",".jpg") -> Think 2.jpg
A12: trial | B12: =masterlist!C11 -> paint | C12: =masterlist!I11 -> рисовать | D12: =masterlist!J11 -> 42.mp4 | E12: =CONCATENATE(PROPER(B12)," 2",".jpg") -> Paint 2.jpg
A13: trial | B13: =masterlist!C12 -> watch | C13: =masterlist!I12 -> смотреть | D13: =masterlist!J12 -> 47.mp4 | E13: =CONCATENATE(PROPER(B13)," 2",".jpg") -> Watch 2.jpg
A14: trial | B14: =masterlist!C13 -> write | C14: =masterlist!I13 -> писать | D14: =masterlist!J13 -> 48.mp4 | E14: =CONCATENATE(PROPER(B14)," 2",".jpg") -> Write 2.jpg
... A26: trial | B26: =masterlist!C25 -> take | C26: =masterlist!I25 -> взять | D26: =masterlist!J25 -> 45.mp4 | E26: =CONCATENATE(PROPER(B26)," 2",".jpg") -> Take 2.jpg
A27: trial | B27: =masterlist!C26 -> frog | C27: =masterlist!I26 -> лягушка | D27: =masterlist!J26 -> 6.mp4 | E27: =CONCATENATE(PROPER(B27)," 1",".jpg") -> Frog 1.jpg
A28: trial | B28: =masterlist!C27 -> gorilla | C28: =masterlist!I27 -> горилла | D28: =masterlist!J27 -> 7.mp4 | E28: =CONCATENATE(PROPER(B28)," 1",".jpg") -> Gorilla 1.jpg
A29: trial | B29: =masterlist!C28 -> come | C29: =masterlist!I28 -> прийти | D29: =masterlist!J28 -> 14.mp4 | E29: =CONCATENATE(PROPER(B29)," 1",".jpg") -> Come 1.jpg
A30: trial | B30: =masterlist!C29 -> sail | C30: =masterlist!I29 -> плыть лодка | D30: =masterlist!J29 -> 18.mp4 | E30: =CONCATENATE(PROPER(B30)," 1",".jpg") -> Sail 1.jpg
A31: trial | B31: =masterlist!C30 -> travel | C31: =masterlist!I30 -> путешествовать | D31: =masterlist!J30 -> 21.mp4 | E31: =CONCATENATE(PROPER(B31)," 1",".jpg") -> Travel 1.jpg
A32: trial | B32: =masterlist!C31 -> doubt | C32: =masterlist!I31 -> сомневаться | D32: =masterlist!J31 -> 15.mp4 | E32: =CONCATENATE(PROPER(B32)," 1",".jpg") -> Doubt 1.jpg
A33: trial | B33: =masterlist!C32 -> play | C33: =masterlist!I32 -> играть | D33: =masterlist!J32 -> 16.mp4 | E33: =CONCATENATE(PROPER(B33)," 1",".jpg") -> Play 1.jpg
A34: trial | B34: =masterlist!C33 -> engagement | C34: =masterlist!I33 -> помолвка | D34: =masterlist!J33 -> 2.mp4 | E34: =CONCATENATE(PROPER(B34)," 1",".jpg") -> Engagement 1.jpg
A35: trial | B35: =masterlist!C34 -> color | C35: =masterlist!I34 -> цвет | D35: =masterlist!J34 -> 3.mp4 | E35: =CONCATENATE(PROPER(B35)," 1",".jpg") -> Color 1.jpg
A36: trial | B36: =masterlist!C35 -> east | C36: =masterlist!I35 -> восток | D36: =masterlist!J35 -> 5.mp4 | E36: =CONCATENATE(PROPER(B36)," 1",".jpg") -> East 1.jpg
A37: trial | B37: =masterlist!C36 -> school | C37: =masterlist!I36 -> школа | D37: =masterlist!J36 -> 11.mp4 | E37: =CONCATENATE(PROPER(B37)," 1",".jpg") -> School 1.jpg
A38: trial | B38: =masterlist!C37 -> pain | C38: =masterlist!I37 -> боль | D38: =masterlist!J37 -> 12.mp4 | E38: =CONCATENATE(PROPER(B38)," 1",".jpg") -> Pain 1.jpg
... A50: trial | B50: =masterlist!C49 -> win | C50: =masterlist!I49 -> победить | D50: =masterlist!J49 -> 24.mp4 | E50: =CONCATENATE(PROPER(B50)," 1",".jpg") -> Win 1.jpg
A51: End

Sheet foils
A1: item | B1: wordclass | C1: noun | D1: norwegian | E1: nsl | F1: nsl_name | G1: russian | H1: rsl_name | I1: rsl_name
A2: 1 | B2: verb | C2: draw | D2: tegne | E2: https://www.minetegn.no/Tegnordbok-HTML/videos/tegne.mp4 | F2: =CONCATENATE(PROPER(D2),".mp4") -> Tegne.mp4 | G2: рисовать | H2: https://media.spreadthesign.com/video/mp4/12/16819.mp4 | I2: =CONCATENATE(A2+48,".mp4") -> 49.mp4
A3: 2 | B3: noun | C3: football | D3: fotball | E3: https://www.minetegn.no/Tegnordbok-HTML/videos/fotball.mp4 | F3: =CONCATENATE(PROPER(D3),".mp4") -> Fotball.mp4 | G3: футбол | H3: https://media.spreadthesign.com/video/mp4/12/4614.mp4 | I3: =CONCATENATE(A3+48,".mp4") -> 50.mp4
A4: 3 | B4: noun | C4: street | D4: gate | E4: https://www.minetegn.no/Tegnordbok-HTML/videos/gate.mp4 | F4: =CONCATENATE(PROPER(D4),".mp4") -> Gate.mp4 | G4: улица | H4: https://media.spreadthesign.com/video/mp4/12/15370.mp4 | I4: =CONCATENATE(A4+48,".mp4") -> 51.mp4
A5: 4 | B5: verb | C5: talk | D5: snakke | E5: https://www.minetegn.no/Tegnordbok-HTML/videos/snakke.mp4 | F5: =CONCATENATE(PROPER(D5),".mp4") -> Snakke.mp4 | G5: разговаривать | H5: https://media.spreadthesign.com/video/mp4/13/50902.mp4 | I5: =CONCATENATE(A5+48,".mp4") -> 52.mp4
A6: 5 | B6: noun | C6: church | D6: kirke | E6: https://www.minetegn.no/Tegnordbok-HTML/videos/kirke.mp4 | F6: =CONCATENATE(PROPER(D6),".mp4") -> Kirke.mp4 | G6: церковь | H6: https://media.spreadthesign.com/video/mp4/12/31703.mp4 | I6: =CONCATENATE(A6+48,".mp4") -> 53.mp4
A7: 6 | B7: verb | C7: invite | D7: invitere | E7: https://www.minetegn.no/Tegnordbok-HTML/videos/invitere.mp4 | F7: =CONCATENATE(PROPER(D7),".mp4") -> Invitere.mp4 | G7: приглашать | H7: https://media.spreadthesign.com/video/mp4/12/5119.mp4 | I7: =CONCATENATE(A7+48,".mp4") -> 54.mp4
A8: 7 | B8: noun | C8: earth | D8: jord | E8: https://www.minetegn.no/Tegnordbok-HTML/videos/jord-2.mp4 | F8: =CONCATENATE(PROPER(D8),".mp4") -> Jord.mp4 | G8: земля | H8: https://media.spreadthesign.com/video/mp4/12/17154.mp4 | I8: =CONCATENATE(A8+48,".mp4") -> 55.mp4
A9: 8 | B9: verb | C9: move | D9: flytte | E9: https://www.minetegn.no/Tegnordbok-HTML/videos/flytte-2.mp4 | F9: =CONCATENATE(PROPER(D9),".mp4") -> Flytte.mp4 | G9: двигаться | H9: https://media.spreadthesign.com/video/mp4/12/43293.mp4 | I9: =CONCATENATE(A9+48,".mp4") -> 56.mp4
A10: 9 | B10: verb | C10: die | D10: dø | E10: https://www.minetegn.no/Tegnordbok-HTML/videos/doe.mp4 | F10: =CONCATENATE(PROPER(D10),".mp4") -> Dø.mp4 | G10: умереть | H10: https://media.spreadthesign.com/video/mp4/12/16417.mp4 | I10: =CONCATENATE(A10+48,".mp4") -> 57.mp4
A11: 10 | B11: noun | C11: meat | D11: kjøtt | E11: https://www.minetegn.no/Tegnordbok-HTML/videos/kjoett.mp4 | F11: =CONCATENATE(PROPER(D11),".mp4") -> Kjøtt.mp4 | G11: мясо | H11: https://media.spreadthesign.com/video/mp4/12/10060.mp4 | I11: =CONCATENATE(A11+48,".mp4") -> 58.mp4
A12: 11 | B12: verb | C12: hunt | D12: jakt | E12: https://www.minetegn.no/Tegnordbok-HTML/videos/jakt.mp4 | F12: =CONCATENATE(PROPER(D12),".mp4") -> Jakt.mp4 | G12: охотиться | H12: https://media.spreadthesign.com/video/mp4/12/296544.mp4 | I12: =CONCATENATE(A12+48,".mp4") -> 59.mp4
A13: 12 | B13: noun | C13: snow | D13: snø | E13: https://www.minetegn.no/Tegnordbok-HTML/videos/snoe.mp4 | F13: =CONCATENATE(PROPER(D13),".mp4") -> Snø.mp4 | G13: снег | H13: https://media.spreadthesign.com/video/mp4/12/99932.mp4 | I13: =CONCATENATE(A13+48,".mp4") -> 60.mp4
... A49: 48 | B49: verb | C49: hope | D49: håpe | E49: https://www.minetegn.no/Tegnordbok-HTML/videos/haape.mp4 | F49: =CONCATENATE(PROPER(D49),".mp4") -> Håpe.mp4 | G49: надеяться | H49: https://media.spreadthesign.com/video/mp4/12/100397.mp4 | I49: =CONCATENATE(A49+48,".mp4") -> 96.mp4

Sheet nsl_list1
A1: display | B1: picture | C1: video | D1: condition | E1: correct | F1: trial | G1: item | H1: index
A2: instructions
A3: match | B3: =IF(D3="same",CONCATENATE(PROPER(G3)," ","1.jpg"),IF(D3="different",CONCATENATE(PROPER(G3)," ","2.jpg"))) -> Boy 1.jpg | C3: =masterlist!D2 -> Gutt.mp4 | D3: same | E3: same | F3: target | G3: =masterlist!C2 -> boy | H3: 1 | I3: noncognate
A4: match | B4: =IF(D4="same",CONCATENATE(PROPER(G4)," ","1.jpg"),IF(D4="different",CONCATENATE(PROPER(G4)," ","2.jpg"))) -> Children 1.jpg | C4: =masterlist!D3 -> Barn.mp4 | D4: same | E4: same | F4: target | G4: =masterlist!C3 -> children | H4: 2 | I4: noncognate
A5: match | B5: =IF(D5="same",CONCATENATE(PROPER(G5)," ","1.jpg"),IF(D5="different",CONCATENATE(PROPER(G5)," ","2.jpg"))) -> Eagle 1.jpg | C5: =masterlist!D4 -> Ørn.mp4 | D5: same | E5: same | F5: target | G5: =masterlist!C4 -> eagle | H5: 3 | I5: noncognate
A6: match | B6: =IF(D6="same",CONCATENATE(PROPER(G6)," ","1.jpg"),IF(D6="different",CONCATENATE(PROPER(G6)," ","2.jpg"))) -> Family 1.jpg | C6: =masterlist!D5 -> Familie.mp4 | D6: same | E6: same | F6: target | G6: =masterlist!C5 -> family | H6: 4 | I6: noncognate
A7: match | B7: =IF(D7="same",CONCATENATE(PROPER(G7)," ","1.jpg"),IF(D7="different",CONCATENATE(PROPER(G7)," ","2.jpg"))) -> Breathe 1.jpg | C7: =masterlist!D6 -> Puste.mp4 | D7: same | E7: same | F7: target | G7: =masterlist!C6 -> breathe | H7: 5 | I7: noncognate
A8: match | B8: =IF(D8="same",CONCATENATE(PROPER(G8)," ","1.jpg"),IF(D8="different",CONCATENATE(PROPER(G8)," ","2.jpg"))) -> Cry 1.jpg | C8: =masterlist!D7 -> Gråte.mp4 | D8: same | E8: same | F8: target | G8: =masterlist!C7 -> cry | H8: 6 | I8: noncognate
A9: match | B9: =IF(D9="same",CONCATENATE(PROPER(G9)," ","1.jpg"),IF(D9="different",CONCATENATE(PROPER(G9)," ","2.jpg"))) -> Run 2.jpg | C9: =masterlist!D8 -> Løpe.mp4 | D9: different | E9: same | F9: target | G9: =masterlist!C8 -> run | H9: 7 | I9: noncognate
A10: match | B10: =IF(D10="same",CONCATENATE(PROPER(G10)," ","1.jpg"),IF(D10="different",CONCATENATE(PROPER(G10)," ","2.jpg"))) -> Sing 2.jpg | C10: =masterlist!D9 -> Synge.mp4 | D10: different | E10: same | F10: target | G10: =masterlist!C9 -> sing | H10: 8 | I10: noncognate
A11: match | B11: =IF(D11="same",CONCATENATE(PROPER(G11)," ","1.jpg"),IF(D11="different",CONCATENATE(PROPER(G11)," ","2.jpg"))) -> Think 2.jpg | C11: =masterlist!D10 -> Tror.mp4 | D11: different | E11: same | F11: target | G11: =masterlist!C10 -> think | H11: 9 | I11: noncognate
A12: match | B12: =IF(D12="same",CONCATENATE(PROPER(G12)," ","1.jpg"),IF(D12="different",CONCATENATE(PROPER(G12)," ","2.jpg"))) -> Paint 2.jpg | C12: =masterlist!D11 -> Male.mp4 | D12: different | E12: same | F12: target | G12: =masterlist!C11 -> paint | H12: 10 | I12: noncognate
A13: match | B13: =IF(D13="same",CONCATENATE(PROPER(G13)," ","1.jpg"),IF(D13="different",CONCATENATE(PROPER(G13)," ","2.jpg"))) -> Watch 2.jpg | C13: =masterlist!D12 -> Se-på.mp4 | D13: different | E13: same | F13: target | G13: =masterlist!C12 -> watch | H13: 11 | I13: noncognate
A14: match | B14: =IF(D14="same",CONCATENATE(PROPER(G14)," ","1.jpg"),IF(D14="different",CONCATENATE(PROPER(G14)," ","2.jpg"))) -> Write 2.jpg | C14: =masterlist!D13 -> Skrive.mp4 | D14: different | E14: same | F14: target | G14: =masterlist!C13 -> write | H14: 12 | I14: noncognate
... A50: match | B50: =IF(D50="same",CONCATENATE(PROPER(G50)," ","1.jpg"),IF(D50="different",CONCATENATE(PROPER(G50)," ","2.jpg"))) -> Win 2.jpg | C50: =masterlist!D49 -> Vinne.mp4 | D50: different | E50: same | F50: target | G50: =masterlist!C49 -> win | H50: 48 | I50: cognate
A51: nomatch | B51: =nsl_list2!B3 -> Boy 2.jpg | C51: =foils!F2 -> Tegne.mp4 | D51: different | E51: different | F51: foil | G51: na | H51: 49 | I51: cognate
A52: nomatch | B52: =nsl_list2!B4 -> Children 2.jpg | C52: =foils!F3 -> Fotball.mp4 | D52: different | E52: different | F52: foil | G52: na | H52: 50
A53: nomatch | B53: =nsl_list2!B5 -> Eagle 2.jpg | C53: =foils!F4 -> Gate.mp4 | D53: different | E53: different | F53: foil | G53: na | H53: 51
A54: nomatch | B54: =nsl_list2!B6 -> Family 2.jpg | C54: =foils!F5 -> Snakke.mp4 | D54: different | E54: different | F54: foil | G54: na | H54: 52
A55: nomatch | B55: =nsl_list2!B7 -> Breathe 2.jpg | C55: =foils!F6 -> Kirke.mp4 | D55: different | E55: different | F55: foil | G55: na | H55: 53
A56: nomatch | B56: =nsl_list2!B8 -> Cry 2.jpg | C56: =foils!F7 -> Invitere.mp4 | D56: different | E56: different | F56: foil | G56: na | H56: 54
A57: nomatch | B57: =nsl_list2!B9 -> Run 1.jpg | C57: =foils!F8 -> Jord.mp4 | D57: different | E57: different | F57: foil | G57: na | H57: 55
A58: nomatch | B58: =nsl_list2!B10 -> Sing 1.jpg | C58: =foils!F9 -> Flytte.mp4 | D58: different | E58: different | F58: foil | G58: na | H58: 56
A59: nomatch | B59: =nsl_list2!B11 -> Think 1.jpg | C59: =foils!F10 -> Dø.mp4 | D59: different | E59: different | F59: foil | G59: na | H59: 57
A60: nomatch | B60: =nsl_list2!B12 -> Paint 1.jpg | C60: =foils!F11 -> Kjøtt.mp4 | D60: different | E60: different | F60: foil | G60: na | H60: 58
A61: nomatch | B61: =nsl_list2!B13 -> Watch 1.jpg | C61: =foils!F12 -> Jakt.mp4 | D61: different | E61: different | F61: foil | G61: na | H61: 59
A62: nomatch | B62: =nsl_list2!B14 -> Write 1.jpg | C62: =foils!F13 -> Snø.mp4 | D62: different | E62: different | F62: foil | G62: na | H62: 60
A63: nomatch | B63: =nsl_list2!B15 -> Beauty 2.jpg | C63: =foils!F14 -> Blod.mp4 | D63: different | E63: different | F63: foil | G63: na | H63: 61
... A98: nomatch | B98: =nsl_list2!B50 -> Write 1.jpg | C98: =foils!F49 -> Håpe.mp4 | D98: different | E98: different | F98: foil | G98: na | H98: 96
A99: end | C99: =foils!F50 -> 0

Sheet nsl_list2
A1: display | B1: picture | C1: video | D1: condition | E1: correct | F1: trial | G1: item | H1: index
A2: instructions
A3: match | B3: =IF(D3="same",CONCATENATE(PROPER(G3)," ","1.jpg"),IF(D3="different",CONCATENATE(PROPER(G3)," ","2.jpg"))) -> Boy 2.jpg | C3: =masterlist!D2 -> Gutt.mp4 | D3: different | E3: same | F3: target | G3: =masterlist!C2 -> boy | H3: 1 | I3: noncognate
A4: match | B4: =IF(D4="same",CONCATENATE(PROPER(G4)," ","1.jpg"),IF(D4="different",CONCATENATE(PROPER(G4)," ","2.jpg"))) -> Children 2.jpg | C4: =masterlist!D3 -> Barn.mp4 | D4: different | E4: same | F4: target | G4: =masterlist!C3 -> children | H4: 2 | I4: noncognate
A5: match | B5: =IF(D5="same",CONCATENATE(PROPER(G5)," ","1.jpg"),IF(D5="different",CONCATENATE(PROPER(G5)," ","2.jpg"))) -> Eagle 2.jpg | C5: =masterlist!D4 -> Ørn.mp4 | D5: different | E5: same | F5: target | G5: =masterlist!C4 -> eagle | H5: 3 | I5: noncognate
A6: match | B6: =IF(D6="same",CONCATENATE(PROPER(G6)," ","1.jpg"),IF(D6="different",CONCATENATE(PROPER(G6)," ","2.jpg"))) -> Family 2.jpg | C6: =masterlist!D5 -> Familie.mp4 | D6: different | E6: same | F6: target | G6: =masterlist!C5 -> family | H6: 4 | I6: noncognate
A7: match | B7: =IF(D7="same",CONCATENATE(PROPER(G7)," ","1.jpg"),IF(D7="different",CONCATENATE(PROPER(G7)," ","2.jpg"))) -> Breathe 2.jpg | C7: =masterlist!D6 -> Puste.mp4 | D7: different | E7: same | F7: target | G7: =masterlist!C6 -> breathe | H7: 5 | I7: noncognate
A8: match | B8: =IF(D8="same",CONCATENATE(PROPER(G8)," ","1.jpg"),IF(D8="different",CONCATENATE(PROPER(G8)," ","2.jpg"))) -> Cry 2.jpg | C8: =masterlist!D7 -> Gråte.mp4 | D8: different | E8: same | F8: target | G8: =masterlist!C7 -> cry | H8: 6 | I8: noncognate
A9: match | B9: =IF(D9="same",CONCATENATE(PROPER(G9)," ","1.jpg"),IF(D9="different",CONCATENATE(PROPER(G9)," ","2.jpg"))) -> Run 1.jpg | C9: =masterlist!D8 -> Løpe.mp4 | D9: same | E9: same | F9: target | G9: =masterlist!C8 -> run | H9: 7 | I9: noncognate
A10: match | B10: =IF(D10="same",CONCATENATE(PROPER(G10)," ","1.jpg"),IF(D10="different",CONCATENATE(PROPER(G10)," ","2.jpg"))) -> Sing 1.jpg | C10: =masterlist!D9 -> Synge.mp4 | D10: same | E10: same | F10: target | G10: =masterlist!C9 -> sing | H10: 8 | I10: noncognate
A11: match | B11: =IF(D11="same",CONCATENATE(PROPER(G11)," ","1.jpg"),IF(D11="different",CONCATENATE(PROPER(G11)," ","2.jpg"))) -> Think 1.jpg | C11: =masterlist!D10 -> Tror.mp4 | D11: same | E11: same | F11: target | G11: =masterlist!C10 -> think | H11: 9 | I11: noncognate
A12: match | B12: =IF(D12="same",CONCATENATE(PROPER(G12)," ","1.jpg"),IF(D12="different",CONCATENATE(PROPER(G12)," ","2.jpg"))) -> Paint 1.jpg | C12: =masterlist!D11 -> Male.mp4 | D12: same | E12: same | F12: target | G12: =masterlist!C11 -> paint | H12: 10 | I12: noncognate
A13: match | B13: =IF(D13="same",CONCATENATE(PROPER(G13)," ","1.jpg"),IF(D13="different",CONCATENATE(PROPER(G13)," ","2.jpg"))) -> Watch 1.jpg | C13: =masterlist!D12 -> Se-på.mp4 | D13: same | E13: same | F13: target | G13: =masterlist!C12 -> watch | H13: 11 | I13: noncognate
A14: match | B14: =IF(D14="same",CONCATENATE(PROPER(G14)," ","1.jpg"),IF(D14="different",CONCATENATE(PROPER(G14)," ","2.jpg"))) -> Write 1.jpg | C14: =masterlist!D13 -> Skrive.mp4 | D14: same | E14: same | F14: target | G14: =masterlist!C13 -> write | H14: 12 | I14: noncognate
... A44: match | B44: =IF(D44="same",CONCATENATE(PROPER(G44)," ","1.jpg"),IF(D44="different",CONCATENATE(PROPER(G44)," ","2.jpg"))) -> Sneeze 2.jpg | C44: =masterlist!D43 -> Nyse.mp4 | D44: different | E44: same | F44: target | G44: =masterlist!C43 -> sneeze | H44: 42 | I44: cognate
A45: match | B45: =IF(D45="same",CONCATENATE(PROPER(G45)," ","1.jpg"),IF(D45="different",CONCATENATE(PROPER(G45)," ","2.jpg"))) -> Try 1.jpg | C45: Gråte.mp4 | D45: same | E45: same | F45: target | G45: =masterlist!C44 -> try | H45: 43 | I45: cognate
A46: match | B46: =IF(D46="same",CONCATENATE(PROPER(G46)," ","1.jpg"),IF(D46="different",CONCATENATE(PROPER(G46)," ","2.jpg"))) -> Wait 1.jpg | C46: Stikke-av.mp4 | D46: same | E46: same | F46: target | G46: =masterlist!C45 -> wait | H46: 44 | I46: cognate
A47: match | B47: =IF(D47="same",CONCATENATE(PROPER(G47)," ","1.jpg"),IF(D47="different",CONCATENATE(PROPER(G47)," ","2.jpg"))) -> Call 1.jpg | C47: Male.mp4 | D47: same | E47: same | F47: target | G47: =masterlist!C46 -> call | H47: 45 | I47: cognate
A48: match | B48: =IF(D48="same",CONCATENATE(PROPER(G48)," ","1.jpg"),IF(D48="different",CONCATENATE(PROPER(G48)," ","2.jpg"))) -> Choose 1.jpg | C48: Synge.mp4 | D48: same | E48: same | F48: target | G48: =masterlist!C47 -> choose | H48: 46 | I48: cognate
A49: match | B49: =IF(D49="same",CONCATENATE(PROPER(G49)," ","1.jpg"),IF(D49="different",CONCATENATE(PROPER(G49)," ","2.jpg"))) -> Show 1.jpg | C49: Tror.mp4 | D49: same | E49: same | F49: target | G49: =masterlist!C48 -> show | H49: 47 | I49: cognate
A50: match | B50: =IF(D50="same",CONCATENATE(PROPER(G50)," ","1.jpg"),IF(D50="different",CONCATENATE(PROPER(G50)," ","2.jpg"))) -> Write 1.jpg | C50: Skrive.mp4 | D50: same | E50: same | F50: target | G50: write | H50: 48 | I50: cognate
A51: nomatch | B51: =nsl_list1!B3 -> Boy 1.jpg | C51: Tegne.mp4 | D51: different | E51: different | F51: foil | G51: na | H51: 49 | I51: cognate
A52: nomatch | B52: =nsl_list1!B4 -> Children 1.jpg | C52: Fotball.mp4 | D52: different | E52: different | F52: foil | G52: na | H52: 50
A53: nomatch | B53: =nsl_list1!B5 -> Eagle 1.jpg | C53: Gate.mp4 | D53: different | E53: different | F53: foil | G53: na | H53: 51
A54: nomatch | B54: =nsl_list1!B6 -> Family 1.jpg | C54: Snakke.mp4 | D54: different | E54: different | F54: foil | G54: na | H54: 52
A55: nomatch | B55: =nsl_list1!B7 -> Breathe 1.jpg | C55: Kirke.mp4 | D55: different | E55: different | F55: foil | G55: na | H55: 53
A56: nomatch | B56: =nsl_list1!B8 -> Cry 1.jpg | C56: Invitere.mp4 | D56: different | E56: different | F56: foil | G56: na | H56: 54
A57: nomatch | B57: =nsl_list1!B9 -> Run 2.jpg | C57: Jord.mp4 | D57: different | E57: different | F57: foil | G57: na | H57: 55
A58: nomatch | B58: =nsl_list1!B10 -> Sing 2.jpg | C58: Flytte.mp4 | D58: different | E58: different | F58: foil | G58: na | H58: 56
A59: nomatch | B59: =nsl_list1!B11 -> Think 2.jpg | C59: Dø.mp4 | D59: different | E59: different | F59: foil | G59: na | H59: 57
A60: nomatch | B60: =nsl_list1!B12 -> Paint 2.jpg | C60: Kjøtt.mp4 | D60: different | E60: different | F60: foil | G60: na | H60: 58
A61: nomatch | B61: =nsl_list1!B13 -> Watch 2.jpg | C61: Jakt.mp4 | D61: different | E61: different | F61: foil | G61: na | H61: 59
A62: nomatch | B62: =nsl_list1!B14 -> Write 2.jpg | C62: Snø.mp4 | D62: different | E62: different | F62: foil | G62: na | H62: 60
A63: nomatch | B63: =nsl_list1!B15 -> Beauty 1.jpg | C63: Blod.mp4 | D63: different | E63: different | F63: foil | G63: na | H63: 61
... A98: nomatch | B98: =nsl_list1!B50 -> Win 2.jpg | C98: Håpe.mp4 | D98: different | E98: different | F98: foil | G98: na | H98: 96
A99: end

Sheet rsl_list1
A1: display | B1: picture | C1: video | D1: condition | E1: correct | F1: trial | G1: item | H1: index
A2: instructions
A3: match | B3: =IF(D3="same",CONCATENATE(PROPER(G3)," ","2.jpg"),IF(D3="different",CONCATENATE(PROPER(G3)," ","1.jpg"))) -> Boy 2.jpg | C3: =masterlist!J2 -> 27.mp4 | D3: same | E3: same | F3: target | G3: =masterlist!C2 -> boy | H3: 1
A4: match | B4: =IF(D4="same",CONCATENATE(PROPER(G4)," ","2.jpg"),IF(D4="different",CONCATENATE(PROPER(G4)," ","1.jpg"))) -> Children 2.jpg | C4: =masterlist!J3 -> 28.mp4 | D4: same | E4: same | F4: target | G4: =masterlist!C3 -> children | H4: 2
A5: match | B5: =IF(D5="same",CONCATENATE(PROPER(G5)," ","2.jpg"),IF(D5="different",CONCATENATE(PROPER(G5)," ","1.jpg"))) -> Eagle 2.jpg | C5: =masterlist!J4 -> 31.mp4 | D5: same | E5: same | F5: target | G5: =masterlist!C4 -> eagle | H5: 3
A6: match | B6: =IF(D6="same",CONCATENATE(PROPER(G6)," ","2.jpg"),IF(D6="different",CONCATENATE(PROPER(G6)," ","1.jpg"))) -> Family 2.jpg | C6: =masterlist!J5 -> 32.mp4 | D6: same | E6: same | F6: target | G6: =masterlist!C5 -> family | H6: 4
A7: match | B7: =IF(D7="same",CONCATENATE(PROPER(G7)," ","2.jpg"),IF(D7="different",CONCATENATE(PROPER(G7)," ","1.jpg"))) -> Breathe 2.jpg | C7: =masterlist!J6 -> 37.mp4 | D7: same | E7: same | F7: target | G7: =masterlist!C6 -> breathe | H7: 5
A8: match | B8: =IF(D8="same",CONCATENATE(PROPER(G8)," ","2.jpg"),IF(D8="different",CONCATENATE(PROPER(G8)," ","1.jpg"))) -> Cry 2.jpg | C8: =masterlist!J7 -> 38.mp4 | D8: same | E8: same | F8: target | G8: =masterlist!C7 -> cry | H8: 6
A9: match | B9: =IF(D9="same",CONCATENATE(PROPER(G9)," ","2.jpg"),IF(D9="different",CONCATENATE(PROPER(G9)," ","1.jpg"))) -> Run 1.jpg | C9: =masterlist!J8 -> 43.mp4 | D9: different | E9: same | F9: target | G9: =masterlist!C8 -> run | H9: 7
A10: match | B10: =IF(D10="same",CONCATENATE(PROPER(G10)," ","2.jpg"),IF(D10="different",CONCATENATE(PROPER(G10)," ","1.jpg"))) -> Sing 1.jpg | C10: =masterlist!J9 -> 44.mp4 | D10: different | E10: same | F10: target | G10: =masterlist!C9 -> sing | H10: 8
A11: match | B11: =IF(D11="same",CONCATENATE(PROPER(G11)," ","2.jpg"),IF(D11="different",CONCATENATE(PROPER(G11)," ","1.jpg"))) -> Think 1.jpg | C11: =masterlist!J10 -> 46.mp4 | D11: different | E11: same | F11: target | G11: =masterlist!C10 -> think | H11: 9
A12: match | B12: =IF(D12="same",CONCATENATE(PROPER(G12)," ","2.jpg"),IF(D12="different",CONCATENATE(PROPER(G12)," ","1.jpg"))) -> Paint 1.jpg | C12: =masterlist!J11 -> 42.mp4 | D12: different | E12: same | F12: target | G12: =masterlist!C11 -> paint | H12: 10
A13: match | B13: =IF(D13="same",CONCATENATE(PROPER(G13)," ","2.jpg"),IF(D13="different",CONCATENATE(PROPER(G13)," ","1.jpg"))) -> Watch 1.jpg | C13: =masterlist!J12 -> 47.mp4 | D13: different | E13: same | F13: target | G13: =masterlist!C12 -> watch | H13: 11
